Workbook

Sheet Pay Bill
A1: Kerala School of Mathematics
A2: Kunnamangalam PO, Kozhikode
A3: Pay Bill Statement for the Month of
A4: EARNINGS
A5: Sl.No. | B5: Name of Employee | C5: Designation | D5: Scale of Pay | E5: Basic | F5: GP/DP | G5: DA | H5: HRA | I5: CCA | J5: Spl.Pay/Deput.Allow | K5: Tr. Allow+DA | L5: Fest. Allow | M5: Others | N5: Gross Pay
A6: 1 | B6: John Doe | C6: Professor | D6: 10000-20000 | E6: 5000 | F6: 1000 | G6: 500 | H6: 200 | I6: 100 | J6: 0 | K6: 0 | L6: 0 | M6: 0 | N6: 6800
C8: UGC/CSIR - DA Rate (%) 7th CPC | D8: 50
C9: State DA (%) 11th Pay | D9: 46
C10: Gross Pay | D10: 6800

Sheet DV-IDENTITY-0
A1: =IF('Pay Bill'!1:1,"AAAAAHxdzQA=",0) -> #VALUE! | B1: =AND('Pay Bill'!A1,"AAAAAHxdzQE=") -> #VALUE! | C1: =AND('Pay Bill'!B1,"AAAAAHxdzQI=") -> #VALUE! | D1: =AND('Pay Bill'!C1,"AAAAAHxdzQM=") -> #VALUE! | E1: =AND('Pay Bill'!D1,"AAAAAHxdzQQ=") -> #VALUE! | F1: =AND('Pay Bill'!E1,"AAAAAHxdzQU=") -> #VALUE! | G1: =AND('Pay Bill'!F1,"AAAAAHxdzQY=") -> #VALUE! | H1: =AND('Pay Bill'!G1,"AAAAAHxdzQc=") -> #VALUE! | I1: =AND('Pay Bill'!H1,"AAAAAHxdzQg=") -> #VALUE! | J1: =AND('Pay Bill'!I1,"AAAAAHxdzQk=") -> #VALUE! | K1: =AND('Pay Bill'!J1,"AAAAAHxdzQo=") -> #VALUE! | L1: =AND('Pay Bill'!#REF!,"AAAAAHxdzQs=") -> #REF! | M1: =AND('Pay Bill'!#REF!,"AAAAAHxdzQw=") -> #REF! | N1: =AND('Pay Bill'!#REF!,"AAAAAHxdzQ0=") -> #REF! | O1: =AND('Pay Bill'!K1,"AAAAAHxdzQ4=") -> #VALUE! | P1: =AND('Pay Bill'!L1,"AAAAAHxdzQ8=") -> #VALUE! | Q1: =AND('Pay Bill'!M1,"AAAAAHxdzRA=") -> #VALUE! | R1: =AND('Pay Bill'!#REF!,"AAAAAHxdzRE=") -> #REF! | S1: =AND('Pay Bill'!#REF!,"AAAAAHxdzRI=") -> #REF! | T1: =AND('Pay Bill'!#REF!,"AAAAAHxdzRM=") -> #REF! | U1: =AND('Pay Bill'!#REF!,"AAAAAHxdzRQ=") -> #REF! | V1: =AND('Pay Bill'!N1,"AAAAAHxdzRU=") -> #VALUE! | W1: =IF('Pay Bill'!2:2,"AAAAAHxdzRY=",0) -> 0 | X1: =AND('Pay Bill'!A2,"AAAAAHxdzRc=") -> #VALUE! | Y1: =AND('Pay Bill'!B2,"AAAAAHxdzRg=") -> #VALUE! | Z1: =AND('Pay Bill'!C2,"AAAAAHxdzRk=") -> #VALUE! | AA1: =AND('Pay Bill'!D2,"AAAAAHxdzRo=") -> #VALUE! | AB1: =AND('Pay Bill'!E2,"AAAAAHxdzRs=") -> #VALUE! | AC1: =AND('Pay Bill'!F2,"AAAAAHxdzRw=") -> #VALUE! | AD1: =AND('Pay Bill'!G2,"AAAAAHxdzR0=") -> #VALUE! | AE1: =AND('Pay Bill'!H2,"AAAAAHxdzR4=") -> #VALUE! | AF1: =AND('Pay Bill'!I2,"AAAAAHxdzR8=") -> #VALUE! | AG1: =AND('Pay Bill'!J2,"AAAAAHxdzSA=") -> #VALUE! | AH1: =AND('Pay Bill'!#REF!,"AAAAAHxdzSE=") -> #REF! | AI1: =AND('Pay Bill'!#REF!,"AAAAAHxdzSI=") -> #REF! | AJ1: =AND('Pay Bill'!#REF!,"AAAAAHxdzSM=") -> #REF! | AK1: =AND('Pay Bill'!K2,"AAAAAHxdzSQ=") -> #VALUE! | AL1: =AND('Pay Bill'!L2,"AAAAAHxdzSU=") -> #VALUE! | AM1: =AND('Pay Bill'!M2,"AAAAAHxdzSY=") -> #VALUE! | AN1: =AND('Pay Bill'!#REF!,"AAAAAHxdzSc=") -> #REF! | AO1: =AND('Pay Bill'!#REF!,"AAAAAHxdzSg=") -> #REF! | AP1: =AND('Pay Bill'!#REF!,"AAAAAHxdzSk=") -> #REF! | AQ1: =AND('Pay Bill'!#REF!,"AAAAAHxdzSo=") -> #REF! | AR1: =AND('Pay Bill'!N2,"AAAAAHxdzSs=") -> #VALUE! | AS1: =IF('Pay Bill'!#REF!,"AAAAAHxdzSw=",0) -> #REF! | AT1: =AND('Pay Bill'!#REF!,"AAAAAHxdzS0=") -> #REF! | AU1: =AND('Pay Bill'!#REF!,"AAAAAHxdzS4=") -> #REF! | AV1: =AND('Pay Bill'!#REF!,"AAAAAHxdzS8=") -> #REF! | AW1: =AND('Pay Bill'!#REF!,"AAAAAHxdzTA=") -> #REF! | AX1: =AND('Pay Bill'!#REF!,"AAAAAHxdzTE=") -> #REF! | AY1: =AND('Pay Bill'!#REF!,"AAAAAHxdzTI=") -> #REF! | AZ1: =AND('Pay Bill'!#REF!,"AAAAAHxdzTM=") -> #REF! | BA1: =AND('Pay Bill'!#REF!,"AAAAAHxdzTQ=") -> #REF! | BB1: =AND('Pay Bill'!#REF!,"AAAAAHxdzTU=") -> #REF! | BC1: =AND('Pay Bill'!#REF!,"AAAAAHxdzTY=") -> #REF! | BD1: =AND('Pay Bill'!#REF!,"AAAAAHxdzTc=") -> #REF! | BE1: =AND('Pay Bill'!#REF!,"AAAAAHxdzTg=") -> #REF! | BF1: =AND('Pay Bill'!#REF!,"AAAAAHxdzTk=") -> #REF! | BG1: =AND('Pay Bill'!#REF!,"AAAAAHxdzTo=") -> #REF! | BH1: =AND('Pay Bill'!#REF!,"AAAAAHxdzTs=") -> #REF! | BI1: =AND('Pay Bill'!#REF!,"AAAAAHxdzTw=") -> #REF! | BJ1: =AND('Pay Bill'!#REF!,"AAAAAHxdzT0=") -> #REF! | BK1: =AND('Pay Bill'!#REF!,"AAAAAHxdzT4=") -> #REF! | BL1: =AND('Pay Bill'!#REF!,"AAAAAHxdzT8=") -> #REF! | BM1: =AND('Pay Bill'!#REF!,"AAAAAHxdzUA=") -> #REF! | BN1: =AND('Pay Bill'!#REF!,"AAAAAHxdzUE=") -> #REF! | BO1: =IF('Pay Bill'!3:3,"AAAAAHxdzUI=",0) -> 0 | BP1: =AND('Pay Bill'!A3,"AAAAAHxdzUM=") -> #VALUE! | BQ1: =AND('Pay Bill'!B3,"AAAAAHxdzUQ=") -> #VALUE! | BR1: =AND('Pay Bill'!C3,"AAAAAHxdzUU=") -> #VALUE! | BS1: =AND('Pay Bill'!D3,"AAAAAHxdzUY=") -> #VALUE! | BT1: =AND('Pay Bill'!E3,"AAAAAHxdzUc=") -> #VALUE! | BU1: =AND('Pay Bill'!F3,"AAAAAHxdzUg=") -> #VALUE! | BV1: =AND('Pay Bill'!G3,"AAAAAHxdzUk=") -> #VALUE! | BW1: =AND('Pay Bill'!H3,"AAAAAHxdzUo=") -> #VALUE! | BX1: =AND('Pay Bill'!I3,"AAAAAHxdzUs=") -> #VALUE! | BY1: =AND('Pay Bill'!J3,"AAAAAHxdzUw=") -> #VALUE! | BZ1: =AND('Pay Bill'!#REF!,"AAAAAHxdzU0=") -> #REF! | CA1: =AND('Pay Bill'!#REF!,"AAAAAHxdzU4=") -> #REF! | CB1: =AND('Pay Bill'!#REF!,"AAAAAHxdzU8=") -> #REF! | CC1: =AND('Pay Bill'!K3,"AAAAAHxdzVA=") -> #VALUE! | CD1: =AND('Pay Bill'!L3,"AAAAAHxdzVE=") -> #VALUE! | CE1: =AND('Pay Bill'!M3,"AAAAAHxdzVI=") -> #VALUE! | CF1: =AND('Pay Bill'!#REF!,"AAAAAHxdzVM=") -> #REF! | CG1: =AND('Pay Bill'!#REF!,"AAAAAHxdzVQ=") -> #REF! | CH1: =AND('Pay Bill'!#REF!,"AAAAAHxdzVU=") -> #REF! | CI1: =AND('Pay Bill'!#REF!,"AAAAAHxdzVY=") -> #REF! | CJ1: =AND('Pay Bill'!N3,"AAAAAHxdzVc=") -> #VALUE! | CK1: =IF('Pay Bill'!4:4,"AAAAAHxdzVg=",0) -> 0 | CL1: =AND('Pay Bill'!A4,"AAAAAHxdzVk=") -> #VALUE! | CM1: =AND('Pay Bill'!B4,"AAAAAHxdzVo=") -> #VALUE! | CN1: =AND('Pay Bill'!C4,"AAAAAHxdzVs=") -> #VALUE! | CO1: =AND('Pay Bill'!D4,"AAAAAHxdzVw=") -> #VALUE! | CP1: =AND('Pay Bill'!E4,"AAAAAHxdzV0=") -> #VALUE! | CQ1: =AND('Pay Bill'!F4,"AAAAAHxdzV4=") -> #VALUE! | CR1: =AND('Pay Bill'!G4,"AAAAAHxdzV8=") -> #VALUE! | CS1: =AND('Pay Bill'!H4,"AAAAAHxdzWA=") -> #VALUE! | CT1: =AND('Pay Bill'!I4,"AAAAAHxdzWE=") -> #VALUE! | CU1: =AND('Pay Bill'!J4,"AAAAAHxdzWI=") -> #VALUE! | CV1: =AND('Pay Bill'!#REF!,"AAAAAHxdzWM=") -> #REF! | CW1: =AND('Pay Bill'!#REF!,"AAAAAHxdzWQ=") -> #REF! | CX1: =AND('Pay Bill'!#REF!,"AAAAAHxdzWU=") -> #REF! | CY1: =AND('Pay Bill'!K4,"AAAAAHxdzWY=") -> #VALUE! | CZ1: =AND('Pay Bill'!L4,"AAAAAHxdzWc=") -> #VALUE! | DA1: =AND('Pay Bill'!M4,"AAAAAHxdzWg=") -> #VALUE! | DB1: =AND('Pay Bill'!#REF!,"AAAAAHxdzWk=") -> #REF! | DC1: =AND('Pay Bill'!#REF!,"AAAAAHxdzWo=") -> #REF! | DD1: =AND('Pay Bill'!#REF!,"AAAAAHxdzWs=") -> #REF! | DE1: =AND('Pay Bill'!#REF!,"AAAAAHxdzWw=") -> #REF! | DF1: =AND('Pay Bill'!N4,"AAAAAHxdzW0=") -> #VALUE! | DG1: =IF('Pay Bill'!5:5,"AAAAAHxdzW4=",0) -> 0 | DH1: =AND('Pay Bill'!A5,"AAAAAHxdzW8=") -> #VALUE! | DI1: =AND('Pay Bill'!B5,"AAAAAHxdzXA=") -> #VALUE! | DJ1: =AND('Pay Bill'!C5,"AAAAAHxdzXE=") -> #VALUE! | DK1: =AND('Pay Bill'!D5,"AAAAAHxdzXI=") -> #VALUE! | DL1: =AND('Pay Bill'!E5,"AAAAAHxdzXM=") -> #VALUE! | DM1: =AND('Pay Bill'!F5,"AAAAAHxdzXQ=") -> #VALUE! | DN1: =AND('Pay Bill'!G5,"AAAAAHxdzXU=") -> #VALUE! | DO1: =AND('Pay Bill'!H5,"AAAAAHxdzXY=") -> #VALUE! | DP1: =AND('Pay Bill'!I5,"AAAAAHxdzXc=") -> #VALUE! | DQ1: =AND('Pay Bill'!J5,"AAAAAHxdzXg=") -> #VALUE! | DR1: =AND('Pay Bill'!#REF!,"AAAAAHxdzXk=") -> #REF! | DS1: =AND('Pay Bill'!#REF!,"AAAAAHxdzXo=") -> #REF! | DT1: =AND('Pay Bill'!#REF!,"AAAAAHxdzXs=") -> #REF! | DU1: =AND('Pay Bill'!K5,"AAAAAHxdzXw=") -> #VALUE! | DV1: =AND('Pay Bill'!L5,"AAAAAHxdzX0=") -> #VALUE! | DW1: =AND('Pay Bill'!M5,"AAAAAHxdzX4=") -> #VALUE! | DX1: =AND('Pay Bill'!#REF!,"AAAAAHxdzX8=") -> #REF! | DY1: =AND('Pay Bill'!#REF!,"AAAAAHxdzYA=") -> #REF! | DZ1: =AND('Pay Bill'!#REF!,"AAAAAHxdzYE=") -> #REF! | EA1: =AND('Pay Bill'!#REF!,"AAAAAHxdzYI=") -> #REF! | EB1: =AND('Pay Bill'!N5,"AAAAAHxdzYM=") -> #VALUE! | EC1: =IF('Pay Bill'!#REF!,"AAAAAHxdzYQ=",0) -> #REF! | ED1: =AND('Pay Bill'!#REF!,"AAAAAHxdzYU=") -> #REF! | EE1: =AND('Pay Bill'!#REF!,"AAAAAHxdzYY=") -> #REF! | EF1: =AND('Pay Bill'!#REF!,"AAAAAHxdzYc=") -> #REF! | EG1: =AND('Pay Bill'!#REF!,"AAAAAHxdzYg=") -> #REF! | EH1: =AND('Pay Bill'!#REF!,"AAAAAHxdzYk=") -> #REF! | EI1: =AND('Pay Bill'!#REF!,"AAAAAHxdzYo=") -> #REF! | EJ1: =AND('Pay Bill'!#REF!,"AAAAAHxdzYs=") -> #REF! | EK1: =AND('Pay Bill'!#REF!,"AAAAAHxdzYw=") -> #REF! | EL1: =AND('Pay Bill'!#REF!,"AAAAAHxdzY0=") -> #REF! | EM1: =AND('Pay Bill'!#REF!,"AAAAAHxdzY4=") -> #REF! | EN1: =AND('Pay Bill'!#REF!,"AAAAAHxdzY8=") -> #REF! | EO1: =AND('Pay Bill'!#REF!,"AAAAAHxdzZA=") -> #REF! | EP1: =AND('Pay Bill'!#REF!,"AAAAAHxdzZE=") -> #REF! | EQ1: =AND('Pay Bill'!#REF!,"AAAAAHxdzZI=") -> #REF! | ER1: =AND('Pay Bill'!#REF!,"AAAAAHxdzZM=") -> #REF! | ES1: =AND('Pay Bill'!#REF!,"AAAAAHxdzZQ=") -> #REF! | ET1: =AND('Pay Bill'!#REF!,"AAAAAHxdzZU=") -> #REF! | EU1: =AND('Pay Bill'!#REF!,"AAAAAHxdzZY=") -> #REF! | EV1: =AND('Pay Bill'!#REF!,"AAAAAHxdzZc=") -> #REF! | EW1: =AND('Pay Bill'!#REF!,"AAAAAHxdzZg=") -> #REF! | EX1: =AND('Pay Bill'!#REF!,"AAAAAHxdzZk=") -> #REF! | EY1: =IF('Pay Bill'!7:7,"AAAAAHxdzZo=",0) -> 0 | EZ1: =AND('Pay Bill'!A7,"AAAAAHxdzZs=") -> #VALUE! | FA1: =AND('Pay Bill'!B7,"AAAAAHxdzZw=") -> #VALUE! | FB1: =AND('Pay Bill'!C7,"AAAAAHxdzZ0=") -> #VALUE! | FC1: =AND('Pay Bill'!D7,"AAAAAHxdzZ4=") -> #VALUE! | FD1: =AND('Pay Bill'!E7,"AAAAAHxdzZ8=") -> #VALUE! | FE1: =AND('Pay Bill'!F7,"AAAAAHxdzaA=") -> #VALUE! | FF1: =AND('Pay Bill'!G7,"AAAAAHxdzaE=") -> #VALUE! | FG1: =AND('Pay Bill'!H7,"AAAAAHxdzaI=") -> #VALUE! | FH1: =AND('Pay Bill'!I7,"AAAAAHxdzaM=") -> #VALUE! | FI1: =AND('Pay Bill'!J7,"AAAAAHxdzaQ=") -> #VALUE! | FJ1: =AND('Pay Bill'!#REF!,"AAAAAHxdzaU=") -> #REF! | FK1: =AND('Pay Bill'!#REF!,"AAAAAHxdzaY=") -> #REF! | FL1: =AND('Pay Bill'!#REF!,"AAAAAHxdzac=") -> #REF! | FM1: =AND('Pay Bill'!K7,"AAAAAHxdzag=") -> #VALUE! | FN1: =AND('Pay Bill'!L7,"AAAAAHxdzak=") -> #VALUE! | FO1: =AND('Pay Bill'!M7,"AAAAAHxdzao=") -> #VALUE! | FP1: =AND('Pay Bill'!#REF!,"AAAAAHxdzas=") -> #REF! | FQ1: =AND('Pay Bill'!#REF!,"AAAAAHxdzaw=") -> #REF! | FR1: =AND('Pay Bill'!#REF!,"AAAAAHxdza0=") -> #REF! | FS1: =AND('Pay Bill'!#REF!,"AAAAAHxdza4=") -> #REF! | FT1: =AND('Pay Bill'!N7,"AAAAAHxdza8=") -> #VALUE! | FU1: =IF('Pay Bill'!#REF!,"AAAAAHxdzbA=",0) -> #REF! | FV1: =AND('Pay Bill'!#REF!,"AAAAAHxdzbE=") -> #REF! | FW1: =AND('Pay Bill'!#REF!,"AAAAAHxdzbI=") -> #REF! | FX1: =AND('Pay Bill'!#REF!,"AAAAAHxdzbM=") -> #REF! | FY1: =AND('Pay Bill'!#REF!,"AAAAAHxdzbQ=") -> #REF! | FZ1: =AND('Pay Bill'!#REF!,"AAAAAHxdzbU=") -> #REF! | GA1: =AND('Pay Bill'!#REF!,"AAAAAHxdzbY=") -> #REF! | GB1: =AND('Pay Bill'!#REF!,"AAAAAHxdzbc=") -> #REF! | GC1: =AND('Pay Bill'!#REF!,"AAAAAHxdzbg=") -> #REF! | GD1: =AND('Pay Bill'!#REF!,"AAAAAHxdzbk=") -> #REF! | GE1: =AND('Pay Bill'!#REF!,"AAAAAHxdzbo=") -> #REF! | GF1: =AND('Pay Bill'!#REF!,"AAAAAHxdzbs=") -> #REF! | GG1: =AND('Pay Bill'!#REF!,"AAAAAHxdzbw=") -> #REF! | GH1: =AND('Pay Bill'!#REF!,"AAAAAHxdzb0=") -> #REF! | GI1: =AND('Pay Bill'!#REF!,"AAAAAHxdzb4=") -> #REF! | GJ1: =AND('Pay Bill'!#REF!,"AAAAAHxdzb8=") -> #REF! | GK1: =AND('Pay Bill'!#REF!,"AAAAAHxdzcA=") -> #REF! | GL1: =AND('Pay Bill'!#REF!,"AAAAAHxdzcE=") -> #REF! | GM1: =AND('Pay Bill'!#REF!,"AAAAAHxdzcI=") -> #REF! | GN1: =AND('Pay Bill'!#REF!,"AAAAAHxdzcM=") -> #REF! | GO1: =AND('Pay Bill'!#REF!,"AAAAAHxdzcQ=") -> #REF! | GP1: =AND('Pay Bill'!#REF!,"AAAAAHxdzcU=") -> #REF! | GQ1: =IF('Pay Bill'!10:10,"AAAAAHxdzcY=",0) -> 0 | GR1: =AND('Pay Bill'!A10,"AAAAAHxdzcc=") -> #VALUE! | GS1: =AND('Pay Bill'!B10,"AAAAAHxdzcg=") -> #VALUE! | GT1: =AND('Pay Bill'!C10,"AAAAAHxdzck=") -> #VALUE! | GU1: =AND('Pay Bill'!D10,"AAAAAHxdzco=") -> #VALUE! | GV1: =AND('Pay Bill'!E10,"AAAAAHxdzcs=") -> #VALUE! | GW1: =AND('Pay Bill'!F10,"AAAAAHxdzcw=") -> #VALUE! | GX1: =AND('Pay Bill'!G10,"AAAAAHxdzc0=") -> #VALUE! | GY1: =AND('Pay Bill'!H10,"AAAAAHxdzc4=") -> #VALUE! | GZ1: =AND('Pay Bill'!I10,"AAAAAHxdzc8=") -> #VALUE! | HA1: =AND('Pay Bill'!J10,"AAAAAHxdzdA=") -> #VALUE! | HB1: =AND('Pay Bill'!#REF!,"AAAAAHxdzdE=") -> #REF! | HC1: =AND('Pay Bill'!#REF!,"AAAAAHxdzdI=") -> #REF! | HD1: =AND('Pay Bill'!#REF!,"AAAAAHxdzdM=") -> #REF! | HE1: =AND('Pay Bill'!K10,"AAAAAHxdzdQ=") -> #VALUE! | HF1: =AND('Pay Bill'!L10,"AAAAAHxdzdU=") -> #VALUE! | HG1: =AND('Pay Bill'!M10,"AAAAAHxdzdY=") -> #VALUE! | HH1: =AND('Pay Bill'!#REF!,"AAAAAHxdzdc=") -> #REF! | HI1: =AND('Pay Bill'!#REF!,"AAAAAHxdzdg=") -> #REF! | HJ1: =AND('Pay Bill'!#REF!,"AAAAAHxdzdk=") -> #REF! | HK1: =AND('Pay Bill'!#REF!,"AAAAAHxdzdo=") -> #REF! | HL1: =AND('Pay Bill'!N10,"AAAAAHxdzds=") -> #VALUE! | HM1: =IF('Pay Bill'!11:11,"AAAAAHxdzdw=",0) -> 0 | HN1: =AND('Pay Bill'!A11,"AAAAAHxdzd0=") -> #VALUE! | HO1: =AND('Pay Bill'!B11,"AAAAAHxdzd4=") -> #VALUE! | HP1: =AND('Pay Bill'!C11,"AAAAAHxdzd8=") -> #VALUE! | HQ1: =AND('Pay Bill'!D11,"AAAAAHxdzeA=") -> #VALUE! | HR1: =AND('Pay Bill'!E11,"AAAAAHxdzeE=") -> #VALUE! | HS1: =AND('Pay Bill'!F11,"AAAAAHxdzeI=") -> #VALUE! | HT1: =AND('Pay Bill'!G11,"AAAAAHxdzeM=") -> #VALUE! | HU1: =AND('Pay Bill'!H11,"AAAAAHxdzeQ=") -> #VALUE! | HV1: =AND('Pay Bill'!I11,"AAAAAHxdzeU=") -> #VALUE! | HW1: =AND('Pay Bill'!J11,"AAAAAHxdzeY=") -> #VALUE! | HX1: =AND('Pay Bill'!#REF!,"AAAAAHxdzec=") -> #REF! | HY1: =AND('Pay Bill'!#REF!,"AAAAAHxdzeg=") -> #REF! | HZ1: =AND('Pay Bill'!#REF!,"AAAAAHxdzek=") -> #REF! | IA1: =AND('Pay Bill'!K11,"AAAAAHxdzeo=") -> #VALUE! | IB1: =AND('Pay Bill'!L11,"AAAAAHxdzes=") -> #VALUE! | IC1: =AND('Pay Bill'!M11,"AAAAAHxdzew=") -> #VALUE! | ID1: =AND('Pay Bill'!#REF!,"AAAAAHxdze0=") -> #REF! | IE1: =AND('Pay Bill'!#REF!,"AAAAAHxdze4=") -> #REF! | IF1: =AND('Pay Bill'!#REF!,"AAAAAHxdze8=") -> #REF! | IG1: =AND('Pay Bill'!#REF!,"AAAAAHxdzfA=") -> #REF! | IH1: =AND('Pay Bill'!N11,"AAAAAHxdzfE=") -> #VALUE! | II1: =IF('Pay Bill'!12:12,"AAAAAHxdzfI=",0) -> 0 | IJ1: =AND('Pay Bill'!A12,"AAAAAHxdzfM=") -> #VALUE! | IK1: =AND('Pay Bill'!B12,"AAAAAHxdzfQ=") -> #VALUE! | IL1: =AND('Pay Bill'!C12,"AAAAAHxdzfU=") -> #VALUE! | IM1: =AND('Pay Bill'!D12,"AAAAAHxdzfY=") -> #VALUE! | IN1: =AND('Pay Bill'!E12,"AAAAAHxdzfc=") -> #VALUE! | IO1: =AND('Pay Bill'!F12,"AAAAAHxdzfg=") -> #VALUE! | IP1: =AND('Pay Bill'!G12,"AAAAAHxdzfk=") -> #VALUE! | IQ1: =AND('Pay Bill'!H12,"AAAAAHxdzfo=") -> #VALUE! | IR1: =AND('Pay Bill'!I12,"AAAAAHxdzfs=") -> #VALUE! | IS1: =AND('Pay Bill'!J12,"AAAAAHxdzfw=") -> #VALUE! | IT1: =AND('Pay Bill'!#REF!,"AAAAAHxdzf0=") -> #REF! | IU1: =AND('Pay Bill'!#REF!,"AAAAAHxdzf4=") -> #REF! | IV1: =AND('Pay Bill'!#REF!,"AAAAAHxdzf8=") -> #REF!
A2: =AND('Pay Bill'!K12,"AAAAAFu4uwA=") -> #VALUE! | B2: =AND('Pay Bill'!L12,"AAAAAFu4uwE=") -> #VALUE! | C2: =AND('Pay Bill'!M12,"AAAAAFu4uwI=") -> #VALUE! | D2: =AND('Pay Bill'!#REF!,"AAAAAFu4uwM=") -> #REF! | E2: =AND('Pay Bill'!#REF!,"AAAAAFu4uwQ=") -> #REF! | F2: =AND('Pay Bill'!#REF!,"AAAAAFu4uwU=") -> #REF! | G2: =AND('Pay Bill'!#REF!,"AAAAAFu4uwY=") -> #REF! | H2: =AND('Pay Bill'!N12,"AAAAAFu4uwc=") -> #VALUE! | I2: =IF('Pay Bill'!#REF!,"AAAAAFu4uwg=",0) -> #REF! | J2: =AND('Pay Bill'!#REF!,"AAAAAFu4uwk=") -> #REF! | K2: =AND('Pay Bill'!#REF!,"AAAAAFu4uwo=") -> #REF! | L2: =AND('Pay Bill'!#REF!,"AAAAAFu4uws=") -> #REF! | M2: =AND('Pay Bill'!#REF!,"AAAAAFu4uww=") -> #REF! | N2: =AND('Pay Bill'!#REF!,"AAAAAFu4uw0=") -> #REF! | O2: =AND('Pay Bill'!#REF!,"AAAAAFu4uw4=") -> #REF! | P2: =AND('Pay Bill'!#REF!,"AAAAAFu4uw8=") -> #REF! | Q2: =AND('Pay Bill'!#REF!,"AAAAAFu4uxA=") -> #REF! | R2: =AND('Pay Bill'!#REF!,"AAAAAFu4uxE=") -> #REF! | S2: =AND('Pay Bill'!#REF!,"AAAAAFu4uxI=") -> #REF! | T2: =AND('Pay Bill'!#REF!,"AAAAAFu4uxM=") -> #REF! | U2: =AND('Pay Bill'!#REF!,"AAAAAFu4uxQ=") -> #REF! | V2: =AND('Pay Bill'!#REF!,"AAAAAFu4uxU=") -> #REF! | W2: =AND('Pay Bill'!#REF!,"AAAAAFu4uxY=") -> #REF! | X2: =AND('Pay Bill'!#REF!,"AAAAAFu4uxc=") -> #REF! | Y2: =AND('Pay Bill'!#REF!,"AAAAAFu4uxg=") -> #REF! | Z2: =AND('Pay Bill'!#REF!,"AAAAAFu4uxk=") -> #REF! | AA2: =AND('Pay Bill'!#REF!,"AAAAAFu4uxo=") -> #REF! | AB2: =AND('Pay Bill'!#REF!,"AAAAAFu4uxs=") -> #REF! | AC2: =AND('Pay Bill'!#REF!,"AAAAAFu4uxw=") -> #REF! | AD2: =AND('Pay Bill'!#REF!,"AAAAAFu4ux0=") -> #REF! | AE2: =IF('Pay Bill'!13:13,"AAAAAFu4ux4=",0) -> 0 | AF2: =AND('Pay Bill'!A13,"AAAAAFu4ux8=") -> #VALUE! | AG2: =AND('Pay Bill'!B13,"AAAAAFu4uyA=") -> #VALUE! | AH2: =AND('Pay Bill'!C13,"AAAAAFu4uyE=") -> #VALUE! | AI2: =AND('Pay Bill'!D13,"AAAAAFu4uyI=") -> #VALUE! | AJ2: =AND('Pay Bill'!E13,"AAAAAFu4uyM=") -> #VALUE! | AK2: =AND('Pay Bill'!F13,"AAAAAFu4uyQ=") -> #VALUE! | AL2: =AND('Pay Bill'!G13,"AAAAAFu4uyU=") -> #VALUE! | AM2: =AND('Pay Bill'!H13,"AAAAAFu4uyY=") -> #VALUE! | AN2: =AND('Pay Bill'!I13,"AAAAAFu4uyc=") -> #VALUE! | AO2: =AND('Pay Bill'!J13,"AAAAAFu4uyg=") -> #VALUE! | AP2: =AND('Pay Bill'!#REF!,"AAAAAFu4uyk=") -> #REF! | AQ2: =AND('Pay Bill'!#REF!,"AAAAAFu4uyo=") -> #REF! | AR2: =AND('Pay Bill'!#REF!,"AAAAAFu4uys=") -> #REF! | AS2: =AND('Pay Bill'!K13,"AAAAAFu4uyw=") -> #VALUE! | AT2: =AND('Pay Bill'!L13,"AAAAAFu4uy0=") -> #VALUE! | AU2: =AND('Pay Bill'!M13,"AAAAAFu4uy4=") -> #VALUE! | AV2: =AND('Pay Bill'!#REF!,"AAAAAFu4uy8=") -> #REF! | AW2: =AND('Pay Bill'!#REF!,"AAAAAFu4uzA=") -> #REF! | AX2: =AND('Pay Bill'!#REF!,"AAAAAFu4uzE=") -> #REF! | AY2: =AND('Pay Bill'!#REF!,"AAAAAFu4uzI=") -> #REF! | AZ2: =AND('Pay Bill'!N13,"AAAAAFu4uzM=") -> #VALUE! | BA2: =IF('Pay Bill'!#REF!,"AAAAAFu4uzQ=",0) -> #REF! | BB2: =AND('Pay Bill'!#REF!,"AAAAAFu4uzU=") -> #REF! | BC2: =AND('Pay Bill'!#REF!,"AAAAAFu4uzY=") -> #REF! | BD2: =AND('Pay Bill'!#REF!,"AAAAAFu4uzc=") -> #REF! | BE2: =AND('Pay Bill'!#REF!,"AAAAAFu4uzg=") -> #REF! | BF2: =AND('Pay Bill'!#REF!,"AAAAAFu4uzk=") -> #REF! | BG2: =AND('Pay Bill'!#REF!,"AAAAAFu4uzo=") -> #REF! | BH2: =AND('Pay Bill'!#REF!,"AAAAAFu4uzs=") -> #REF! | BI2: =AND('Pay Bill'!#REF!,"AAAAAFu4uzw=") -> #REF! | BJ2: =AND('Pay Bill'!#REF!,"AAAAAFu4uz0=") -> #REF! | BK2: =AND('Pay Bill'!#REF!,"AAAAAFu4uz4=") -> #REF! | BL2: =AND('Pay Bill'!#REF!,"AAAAAFu4uz8=") -> #REF! | BM2: =AND('Pay Bill'!#REF!,"AAAAAFu4u0A=") -> #REF! | BN2: =AND('Pay Bill'!#REF!,"AAAAAFu4u0E=") -> #REF! | BO2: =AND('Pay Bill'!#REF!,"AAAAAFu4u0I=") -> #REF! | BP2: =AND('Pay Bill'!#REF!,"AAAAAFu4u0M=") -> #REF! | BQ2: =AND('Pay Bill'!#REF!,"AAAAAFu4u0Q=") -> #REF! | BR2: =AND('Pay Bill'!#REF!,"AAAAAFu4u0U=") -> #REF! | BS2: =AND('Pay Bill'!#REF!,"AAAAAFu4u0Y=") -> #REF! | BT2: =AND('Pay Bill'!#REF!,"AAAAAFu4u0c=") -> #REF! | BU2: =AND('Pay Bill'!#REF!,"AAAAAFu4u0g=") -> #REF! | BV2: =AND('Pay Bill'!#REF!,"AAAAAFu4u0k=") -> #REF! | BW2: =IF('Pay Bill'!#REF!,"AAAAAFu4u0o=",0) -> #REF! | BX2: =AND('Pay Bill'!#REF!,"AAAAAFu4u0s=") -> #REF! | BY2: =AND('Pay Bill'!#REF!,"AAAAAFu4u0w=") -> #REF! | BZ2: =AND('Pay Bill'!#REF!,"AAAAAFu4u00=") -> #REF! | CA2: =AND('Pay Bill'!#REF!,"AAAAAFu4u04=") -> #REF! | CB2: =AND('Pay Bill'!#REF!,"AAAAAFu4u08=") -> #REF! | CC2: =AND('Pay Bill'!#REF!,"AAAAAFu4u1A=") -> #REF! | CD2: =AND('Pay Bill'!#REF!,"AAAAAFu4u1E=") -> #REF! | CE2: =AND('Pay Bill'!#REF!,"AAAAAFu4u1I=") -> #REF! | CF2: =AND('Pay Bill'!#REF!,"AAAAAFu4u1M=") -> #REF! | CG2: =AND('Pay Bill'!#REF!,"AAAAAFu4u1Q=") -> #REF! | CH2: =AND('Pay Bill'!#REF!,"AAAAAFu4u1U=") -> #REF! | CI2: =AND('Pay Bill'!#REF!,"AAAAAFu4u1Y=") -> #REF! | CJ2: =AND('Pay Bill'!#REF!,"AAAAAFu4u1c=") -> #REF! | CK2: =AND('Pay Bill'!#REF!,"AAAAAFu4u1g=") -> #REF! | CL2: =AND('Pay Bill'!#REF!,"AAAAAFu4u1k=") -> #REF! | CM2: =AND('Pay Bill'!#REF!,"AAAAAFu4u1o=") -> #REF! | CN2: =AND('Pay Bill'!#REF!,"AAAAAFu4u1s=") -> #REF! | CO2: =AND('Pay Bill'!#REF!,"AAAAAFu4u1w=") -> #REF! | CP2: =AND('Pay Bill'!#REF!,"AAAAAFu4u10=") -> #REF! | CQ2: =AND('Pay Bill'!#REF!,"AAAAAFu4u14=") -> #REF! | CR2: =AND('Pay Bill'!#REF!,"AAAAAFu4u18=") -> #REF! | CS2: =IF('Pay Bill'!#REF!,"AAAAAFu4u2A=",0) -> #REF! | CT2: =AND('Pay Bill'!#REF!,"AAAAAFu4u2E=") -> #REF! | CU2: =AND('Pay Bill'!#REF!,"AAAAAFu4u2I=") -> #REF! | CV2: =AND('Pay Bill'!#REF!,"AAAAAFu4u2M=") -> #REF! | CW2: =AND('Pay Bill'!#REF!,"AAAAAFu4u2Q=") -> #REF! | CX2: =AND('Pay Bill'!#REF!,"AAAAAFu4u2U=") -> #REF! | CY2: =AND('Pay Bill'!#REF!,"AAAAAFu4u2Y=") -> #REF! | CZ2: =AND('Pay Bill'!#REF!,"AAAAAFu4u2c=") -> #REF! | DA2: =AND('Pay Bill'!#REF!,"AAAAAFu4u2g=") -> #REF! | DB2: =AND('Pay Bill'!#REF!,"AAAAAFu4u2k=") -> #REF! | DC2: =AND('Pay Bill'!#REF!,"AAAAAFu4u2o=") -> #REF! | DD2: =AND('Pay Bill'!#REF!,"AAAAAFu4u2s=") -> #REF! | DE2: =AND('Pay Bill'!#REF!,"AAAAAFu4u2w=") -> #REF! | DF2: =AND('Pay Bill'!#REF!,"AAAAAFu4u20=") -> #REF! | DG2: =AND('Pay Bill'!#REF!,"AAAAAFu4u24=") -> #REF! | DH2: =AND('Pay Bill'!#REF!,"AAAAAFu4u28=") -> #REF! | DI2: =AND('Pay Bill'!#REF!,"AAAAAFu4u3A=") -> #REF! | DJ2: =AND('Pay Bill'!#REF!,"AAAAAFu4u3E=") -> #REF! | DK2: =AND('Pay Bill'!#REF!,"AAAAAFu4u3I=") -> #REF! | DL2: =AND('Pay Bill'!#REF!,"AAAAAFu4u3M=") -> #REF! | DM2: =AND('Pay Bill'!#REF!,"AAAAAFu4u3Q=") -> #REF! | DN2: =AND('Pay Bill'!#REF!,"AAAAAFu4u3U=") -> #REF! | DO2: =IF('Pay Bill'!16:16,"AAAAAFu4u3Y=",0) -> 0 | DP2: =AND('Pay Bill'!A16,"AAAAAFu4u3c=") -> #VALUE! | DQ2: =AND('Pay Bill'!B16,"AAAAAFu4u3g=") -> #VALUE! | DR2: =AND('Pay Bill'!C16,"AAAAAFu4u3k=") -> #VALUE! | DS2: =AND('Pay Bill'!D16,"AAAAAFu4u3o=") -> #VALUE! | DT2: =AND('Pay Bill'!E16,"AAAAAFu4u3s=") -> #VALUE! | DU2: =AND('Pay Bill'!F16,"AAAAAFu4u3w=") -> #VALUE! | DV2: =AND('Pay Bill'!G16,"AAAAAFu4u30=") -> #VALUE! | DW2: =AND('Pay Bill'!H16,"AAAAAFu4u34=") -> #VALUE! | DX2: =AND('Pay Bill'!I16,"AAAAAFu4u38=") -> #VALUE! | DY2: =AND('Pay Bill'!J16,"AAAAAFu4u4A=") -> #VALUE! | DZ2: =AND('Pay Bill'!#REF!,"AAAAAFu4u4E=") -> #REF! | EA2: =AND('Pay Bill'!#REF!,"AAAAAFu4u4I=") -> #REF! | EB2: =AND('Pay Bill'!#REF!,"AAAAAFu4u4M=") -> #REF! | EC2: =AND('Pay Bill'!K16,"AAAAAFu4u4Q=") -> #VALUE! | ED2: =AND('Pay Bill'!L16,"AAAAAFu4u4U=") -> #VALUE! | EE2: =AND('Pay Bill'!M16,"AAAAAFu4u4Y=") -> #VALUE! | EF2: =AND('Pay Bill'!#REF!,"AAAAAFu4u4c=") -> #REF! | EG2: =AND('Pay Bill'!#REF!,"AAAAAFu4u4g=") -> #REF! | EH2: =AND('Pay Bill'!#REF!,"AAAAAFu4u4k=") -> #REF! | EI2: =AND('Pay Bill'!#REF!,"AAAAAFu4u4o=") -> #REF! | EJ2: =AND('Pay Bill'!N16,"AAAAAFu4u4s=") -> #VALUE! | EK2: =IF('Pay Bill'!17:17,"AAAAAFu4u4w=",0) -> 0 | EL2: =AND('Pay Bill'!A17,"AAAAAFu4u40=") -> #VALUE! | EM2: =AND('Pay Bill'!B17,"AAAAAFu4u44=") -> #VALUE! | EN2: =AND('Pay Bill'!C17,"AAAAAFu4u48=") -> #VALUE! | EO2: =AND('Pay Bill'!D17,"AAAAAFu4u5A=") -> #VALUE! | EP2: =AND('Pay Bill'!E17,"AAAAAFu4u5E=") -> #VALUE! | EQ2: =AND('Pay Bill'!F17,"AAAAAFu4u5I=") -> #VALUE! | ER2: =AND('Pay Bill'!G17,"AAAAAFu4u5M=") -> #VALUE! | ES2: =AND('Pay Bill'!H17,"AAAAAFu4u5Q=") -> #VALUE! | ET2: =AND('Pay Bill'!I17,"AAAAAFu4u5U=") -> #VALUE! | EU2: =AND('Pay Bill'!J17,"AAAAAFu4u5Y=") -> #VALUE! | EV2: =AND('Pay Bill'!#REF!,"AAAAAFu4u5c=") -> #REF! | EW2: =AND('Pay Bill'!#REF!,"AAAAAFu4u5g=") -> #REF! | EX2: =AND('Pay Bill'!#REF!,"AAAAAFu4u5k=") -> #REF! | EY2: =AND('Pay Bill'!K17,"AAAAAFu4u5o=") -> #VALUE! | EZ2: =AND('Pay Bill'!L17,"AAAAAFu4u5s=") -> #VALUE! | FA2: =AND('Pay Bill'!M17,"AAAAAFu4u5w=") -> #VALUE! | FB2: =AND('Pay Bill'!#REF!,"AAAAAFu4u50=") -> #REF! | FC2: =AND('Pay Bill'!#REF!,"AAAAAFu4u54=") -> #REF! | FD2: =AND('Pay Bill'!#REF!,"AAAAAFu4u58=") -> #REF! | FE2: =AND('Pay Bill'!#REF!,"AAAAAFu4u6A=") -> #REF! | FF2: =AND('Pay Bill'!N17,"AAAAAFu4u6E=") -> #VALUE! | FG2: =IF('Pay Bill'!#REF!,"AAAAAFu4u6I=",0) -> #REF! | FH2: =AND('Pay Bill'!#REF!,"AAAAAFu4u6M=") -> #REF! | FI2: =AND('Pay Bill'!#REF!,"AAAAAFu4u6Q=") -> #REF! | FJ2: =AND('Pay Bill'!#REF!,"AAAAAFu4u6U=") -> #REF! | FK2: =AND('Pay Bill'!#REF!,"AAAAAFu4u6Y=") -> #REF! | FL2: =AND('Pay Bill'!#REF!,"AAAAAFu4u6c=") -> #REF! | FM2: =AND('Pay Bill'!#REF!,"AAAAAFu4u6g=") -> #REF! | FN2: =AND('Pay Bill'!#REF!,"AAAAAFu4u6k=") -> #REF! | FO2: =AND('Pay Bill'!#REF!,"AAAAAFu4u6o=") -> #REF! | FP2: =AND('Pay Bill'!#REF!,"AAAAAFu4u6s=") -> #REF! | FQ2: =AND('Pay Bill'!#REF!,"AAAAAFu4u6w=") -> #REF! | FR2: =AND('Pay Bill'!#REF!,"AAAAAFu4u60=") -> #REF! | FS2: =AND('Pay Bill'!#REF!,"AAAAAFu4u64=") -> #REF! | FT2: =AND('Pay Bill'!#REF!,"AAAAAFu4u68=") -> #REF! | FU2: =AND('Pay Bill'!#REF!,"AAAAAFu4u7A=") -> #REF! | FV2: =AND('Pay Bill'!#REF!,"AAAAAFu4u7E=") -> #REF! | FW2: =AND('Pay Bill'!#REF!,"AAAAAFu4u7I=") -> #REF! | FX2: =AND('Pay Bill'!#REF!,"AAAAAFu4u7M=") -> #REF! | FY2: =AND('Pay Bill'!#REF!,"AAAAAFu4u7Q=") -> #REF! | FZ2: =AND('Pay Bill'!#REF!,"AAAAAFu4u7U=") -> #REF! | GA2: =AND('Pay Bill'!#REF!,"AAAAAFu4u7Y=") -> #REF! | GB2: =AND('Pay Bill'!#REF!,"AAAAAFu4u7c=") -> #REF! | GC2: =IF('Pay Bill'!19:19,"AAAAAFu4u7g=",0) -> 0 | GD2: =AND('Pay Bill'!A19,"AAAAAFu4u7k=") -> #VALUE! | GE2: =AND('Pay Bill'!B19,"AAAAAFu4u7o=") -> #VALUE! | GF2: =AND('Pay Bill'!C19,"AAAAAFu4u7s=") -> #VALUE! | GG2: =AND('Pay Bill'!D19,"AAAAAFu4u7w=") -> #VALUE! | GH2: =AND('Pay Bill'!E19,"AAAAAFu4u70=") -> #VALUE! | GI2: =AND('Pay Bill'!F19,"AAAAAFu4u74=") -> #VALUE! | GJ2: =AND('Pay Bill'!#REF!,"AAAAAFu4u78=") -> #REF! | GK2: =AND('Pay Bill'!H19,"AAAAAFu4u8A=") -> #VALUE! | GL2: =AND('Pay Bill'!I19,"AAAAAFu4u8E=") -> #VALUE! | GM2: =AND('Pay Bill'!J19,"AAAAAFu4u8I=") -> #VALUE! | GN2: =AND('Pay Bill'!#REF!,"AAAAAFu4u8M=") -> #REF! | GO2: =AND('Pay Bill'!#REF!,"AAAAAFu4u8Q=") -> #REF! | GP2: =AND('Pay Bill'!#REF!,"AAAAAFu4u8U=") -> #REF! | GQ2: =AND('Pay Bill'!K19,"AAAAAFu4u8Y=") -> #VALUE! | GR2: =AND('Pay Bill'!L19,"AAAAAFu4u8c=") -> #VALUE! | GS2: =AND('Pay Bill'!M19,"AAAAAFu4u8g=") -> #VALUE! | GT2: =AND('Pay Bill'!#REF!,"AAAAAFu4u8k=") -> #REF! | GU2: =AND('Pay Bill'!#REF!,"AAAAAFu4u8o=") -> #REF! | GV2: =AND('Pay Bill'!#REF!,"AAAAAFu4u8s=") -> #REF! | GW2: =AND('Pay Bill'!#REF!,"AAAAAFu4u8w=") -> #REF! | GX2: =AND('Pay Bill'!N19,"AAAAAFu4u80=") -> #VALUE! | GY2: =IF('Pay Bill'!#REF!,"AAAAAFu4u84=",0) -> #REF! | GZ2: =AND('Pay Bill'!#REF!,"AAAAAFu4u88=") -> #REF! | HA2: =AND('Pay Bill'!#REF!,"AAAAAFu4u9A=") -> #REF! | HB2: =AND('Pay Bill'!#REF!,"AAAAAFu4u9E=") -> #REF! | HC2: =AND('Pay Bill'!#REF!,"AAAAAFu4u9I=") -> #REF! | HD2: =AND('Pay Bill'!#REF!,"AAAAAFu4u9M=") -> #REF! | HE2: =AND('Pay Bill'!#REF!,"AAAAAFu4u9Q=") -> #REF! | HF2: =AND('Pay Bill'!G19,"AAAAAFu4u9U=") -> #VALUE! | HG2: =AND('Pay Bill'!#REF!,"AAAAAFu4u9Y=") -> #REF! | HH2: =AND('Pay Bill'!#REF!,"AAAAAFu4u9c=") -> #REF! | HI2: =AND('Pay Bill'!#REF!,"AAAAAFu4u9g=") -> #REF! | HJ2: =AND('Pay Bill'!#REF!,"AAAAAFu4u9k=") -> #REF! | HK2: =AND('Pay Bill'!#REF!,"AAAAAFu4u9o=") -> #REF! | HL2: =AND('Pay Bill'!#REF!,"AAAAAFu4u9s=") -> #REF! | HM2: =AND('Pay Bill'!#REF!,"AAAAAFu4u9w=") -> #REF! | HN2: =AND('Pay Bill'!#REF!,"AAAAAFu4u90=") -> #REF! | HO2: =AND('Pay Bill'!#REF!,"AAAAAFu4u94=") -> #REF! | HP2: =AND('Pay Bill'!#REF!,"AAAAAFu4u98=") -> #REF! | HQ2: =AND('Pay Bill'!#REF!,"AAAAAFu4u+A=") -> #REF! | HR2: =AND('Pay Bill'!#REF!,"AAAAAFu4u+E=") -> #REF! | HS2: =AND('Pay Bill'!#REF!,"AAAAAFu4u+I=") -> #REF! | HT2: =AND('Pay Bill'!#REF!,"AAAAAFu4u+M=") -> #REF! | HU2: =IF('Pay Bill'!22:22,"AAAAAFu4u+Q=",0) -> 0 | HV2: =AND('Pay Bill'!A22,"AAAAAFu4u+U=") -> #VALUE! | HW2: =AND('Pay Bill'!B22,"AAAAAFu4u+Y=") -> #VALUE! | HX2: =AND('Pay Bill'!C22,"AAAAAFu4u+c=") -> #VALUE! | HY2: =AND('Pay Bill'!D22,"AAAAAFu4u+g=") -> #VALUE! | HZ2: =AND('Pay Bill'!E22,"AAAAAFu4u+k=") -> #VALUE! | IA2: =AND('Pay Bill'!F22,"AAAAAFu4u+o=") -> #VALUE! | IB2: =AND('Pay Bill'!#REF!,"AAAAAFu4u+s=") -> #REF! | IC2: =AND('Pay Bill'!H22,"AAAAAFu4u+w=") -> #VALUE! | ID2: =AND('Pay Bill'!I22,"AAAAAFu4u+0=") -> #VALUE! | IE2: =AND('Pay Bill'!J22,"AAAAAFu4u+4=") -> #VALUE! | IF2: =AND('Pay Bill'!#REF!,"AAAAAFu4u+8=") -> #REF! | IG2: =AND('Pay Bill'!#REF!,"AAAAAFu4u/A=") -> #REF! | IH2: =AND('Pay Bill'!#REF!,"AAAAAFu4u/E=") -> #REF! | II2: =AND('Pay Bill'!K22,"AAAAAFu4u/I=") -> #VALUE! | IJ2: =AND('Pay Bill'!L22,"AAAAAFu4u/M=") -> #VALUE! | IK2: =AND('Pay Bill'!M22,"AAAAAFu4u/Q=") -> #VALUE! | IL2: =AND('Pay Bill'!#REF!,"AAAAAFu4u/U=") -> #REF! | IM2: =AND('Pay Bill'!#REF!,"AAAAAFu4u/Y=") -> #REF! | IN2: =AND('Pay Bill'!#REF!,"AAAAAFu4u/c=") -> #REF! | IO2: =AND('Pay Bill'!#REF!,"AAAAAFu4u/g=") -> #REF! | IP2: =AND('Pay Bill'!N22,"AAAAAFu4u/k=") -> #VALUE! | IQ2: =IF('Pay Bill'!23:23,"AAAAAFu4u/o=",0) -> 0 | IR2: =AND('Pay Bill'!A23,"AAAAAFu4u/s=") -> #VALUE! | IS2: =AND('Pay Bill'!B23,"AAAAAFu4u/w=") -> #VALUE! | IT2: =AND('Pay Bill'!C23,"AAAAAFu4u/0=") -> #VALUE! | IU2: =AND('Pay Bill'!D23,"AAAAAFu4u/4=") -> #VALUE! | IV2: =AND('Pay Bill'!E23,"AAAAAFu4u/8=") -> #VALUE!
A3: =AND('Pay Bill'!F23,"AAAAAD//ZAA=") -> #VALUE! | B3: =AND('Pay Bill'!G22,"AAAAAD//ZAE=") -> #VALUE! | C3: =AND('Pay Bill'!H23,"AAAAAD//ZAI=") -> #VALUE! | D3: =AND('Pay Bill'!I23,"AAAAAD//ZAM=") -> #VALUE! | E3: =AND('Pay Bill'!J23,"AAAAAD//ZAQ=") -> #VALUE! | F3: =AND('Pay Bill'!#REF!,"AAAAAD//ZAU=") -> #REF! | G3: =AND('Pay Bill'!#REF!,"AAAAAD//ZAY=") -> #REF! | H3: =AND('Pay Bill'!#REF!,"AAAAAD//ZAc=") -> #REF! | I3: =AND('Pay Bill'!K23,"AAAAAD//ZAg=") -> #VALUE! | J3: =AND('Pay Bill'!L23,"AAAAAD//ZAk=") -> #VALUE! | K3: =AND('Pay Bill'!M23,"AAAAAD//ZAo=") -> #VALUE! | L3: =AND('Pay Bill'!#REF!,"AAAAAD//ZAs=") -> #REF! | M3: =AND('Pay Bill'!#REF!,"AAAAAD//ZAw=") -> #REF! | N3: =AND('Pay Bill'!#REF!,"AAAAAD//ZA0=") -> #REF! | O3: =AND('Pay Bill'!#REF!,"AAAAAD//ZA4=") -> #REF! | P3: =AND('Pay Bill'!N23,"AAAAAD//ZA8=") -> #VALUE! | Q3: =IF('Pay Bill'!24:24,"AAAAAD//ZBA=",0) -> 0 | R3: =AND('Pay Bill'!A24,"AAAAAD//ZBE=") -> #VALUE! | S3: =AND('Pay Bill'!B24,"AAAAAD//ZBI=") -> #VALUE! | T3: =AND('Pay Bill'!C24,"AAAAAD//ZBM=") -> #VALUE! | U3: =AND('Pay Bill'!D24,"AAAAAD//ZBQ=") -> #VALUE! | V3: =AND('Pay Bill'!E24,"AAAAAD//ZBU=") -> #VALUE! | W3: =AND('Pay Bill'!F24,"AAAAAD//ZBY=") -> #VALUE! | X3: =AND('Pay Bill'!G23,"AAAAAD//ZBc=") -> #VALUE! | Y3: =AND('Pay Bill'!H24,"AAAAAD//ZBg=") -> #VALUE! | Z3: =AND('Pay Bill'!I24,"AAAAAD//ZBk=") -> #VALUE! | AA3: =AND('Pay Bill'!J24,"AAAAAD//ZBo=") -> #VALUE! | AB3: =AND('Pay Bill'!#REF!,"AAAAAD//ZBs=") -> #REF! | AC3: =AND('Pay Bill'!#REF!,"AAAAAD//ZBw=") -> #REF! | AD3: =AND('Pay Bill'!#REF!,"AAAAAD//ZB0=") -> #REF! | AE3: =AND('Pay Bill'!K24,"AAAAAD//ZB4=") -> #VALUE! | AF3: =AND('Pay Bill'!L24,"AAAAAD//ZB8=") -> #VALUE! | AG3: =AND('Pay Bill'!M24,"AAAAAD//ZCA=") -> #VALUE! | AH3: =AND('Pay Bill'!#REF!,"AAAAAD//ZCE=") -> #REF! | AI3: =AND('Pay Bill'!#REF!,"AAAAAD//ZCI=") -> #REF! | AJ3: =AND('Pay Bill'!#REF!,"AAAAAD//ZCM=") -> #REF! | AK3: =AND('Pay Bill'!#REF!,"AAAAAD//ZCQ=") -> #REF! | AL3: =AND('Pay Bill'!N24,"AAAAAD//ZCU=") -> #VALUE! | AM3: =IF('Pay Bill'!#REF!,"AAAAAD//ZCY=",0) -> #REF! | AN3: =AND('Pay Bill'!#REF!,"AAAAAD//ZCc=") -> #REF! | AO3: =AND('Pay Bill'!#REF!,"AAAAAD//ZCg=") -> #REF! | AP3: =AND('Pay Bill'!#REF!,"AAAAAD//ZCk=") -> #REF! | AQ3: =AND('Pay Bill'!#REF!,"AAAAAD//ZCo=") -> #REF! | AR3: =AND('Pay Bill'!#REF!,"AAAAAD//ZCs=") -> #REF! | AS3: =AND('Pay Bill'!#REF!,"AAAAAD//ZCw=") -> #REF! | AT3: =AND('Pay Bill'!#REF!,"AAAAAD//ZC0=") -> #REF! | AU3: =AND('Pay Bill'!#REF!,"AAAAAD//ZC4=") -> #REF! | AV3: =AND('Pay Bill'!#REF!,"AAAAAD//ZC8=") -> #REF! | AW3: =AND('Pay Bill'!#REF!,"AAAAAD//ZDA=") -> #REF! | AX3: =AND('Pay Bill'!#REF!,"AAAAAD//ZDE=") -> #REF! | AY3: =AND('Pay Bill'!#REF!,"AAAAAD//ZDI=") -> #REF! | AZ3: =AND('Pay Bill'!#REF!,"AAAAAD//ZDM=") -> #REF! | BA3: =AND('Pay Bill'!#REF!,"AAAAAD//ZDQ=") -> #REF! | BB3: =AND('Pay Bill'!#REF!,"AAAAAD//ZDU=") -> #REF! | BC3: =AND('Pay Bill'!#REF!,"AAAAAD//ZDY=") -> #REF! | BD3: =AND('Pay Bill'!#REF!,"AAAAAD//ZDc=") -> #REF! | BE3: =AND('Pay Bill'!#REF!,"AAAAAD//ZDg=") -> #REF! | BF3: =AND('Pay Bill'!#REF!,"AAAAAD//ZDk=") -> #REF! | BG3: =AND('Pay Bill'!#REF!,"AAAAAD//ZDo=") -> #REF! | BH3: =AND('Pay Bill'!#REF!,"AAAAAD//ZDs=") -> #REF! | BI3: =IF('Pay Bill'!25:25,"AAAAAD//ZDw=",0) -> 0 | BJ3: =AND('Pay Bill'!A25,"AAAAAD//ZD0=") -> #VALUE! | BK3: =AND('Pay Bill'!B25,"AAAAAD//ZD4=") -> #VALUE! | BL3: =AND('Pay Bill'!C25,"AAAAAD//ZD8=") -> #VALUE! | BM3: =AND('Pay Bill'!D25,"AAAAAD//ZEA=") -> #VALUE! | BN3: =AND('Pay Bill'!E25,"AAAAAD//ZEE=") -> #VALUE! | BO3: =AND('Pay Bill'!F25,"AAAAAD//ZEI=") -> #VALUE! | BP3: =AND('Pay Bill'!G25,"AAAAAD//ZEM=") -> #VALUE! | BQ3: =AND('Pay Bill'!H25,"AAAAAD//ZEQ=") -> #VALUE! | BR3: =AND('Pay Bill'!I25,"AAAAAD//ZEU=") -> #VALUE! | BS3: =AND('Pay Bill'!J25,"AAAAAD//ZEY=") -> #VALUE! | BT3: =AND('Pay Bill'!#REF!,"AAAAAD//ZEc=") -> #REF! | BU3: =AND('Pay Bill'!#REF!,"AAAAAD//ZEg=") -> #REF! | BV3: =AND('Pay Bill'!#REF!,"AAAAAD//ZEk=") -> #REF! | BW3: =AND('Pay Bill'!K25,"AAAAAD//ZEo=") -> #VALUE! | BX3: =AND('Pay Bill'!L25,"AAAAAD//ZEs=") -> #VALUE! | BY3: =AND('Pay Bill'!M25,"AAAAAD//ZEw=") -> #VALUE! | BZ3: =AND('Pay Bill'!#REF!,"AAAAAD//ZE0=") -> #REF! | CA3: =AND('Pay Bill'!#REF!,"AAAAAD//ZE4=") -> #REF! | CB3: =AND('Pay Bill'!#REF!,"AAAAAD//ZE8=") -> #REF! | CC3: =AND('Pay Bill'!#REF!,"AAAAAD//ZFA=") -> #REF! | CD3: =AND('Pay Bill'!N25,"AAAAAD//ZFE=") -> #VALUE! | CE3: =IF('Pay Bill'!#REF!,"AAAAAD//ZFI=",0) -> #REF! | CF3: =AND('Pay Bill'!#REF!,"AAAAAD//ZFM=") -> #REF! | CG3: =AND('Pay Bill'!#REF!,"AAAAAD//ZFQ=") -> #REF! | CH3: =AND('Pay Bill'!#REF!,"AAAAAD//ZFU=") -> #REF! | CI3: =AND('Pay Bill'!#REF!,"AAAAAD//ZFY=") -> #REF! | CJ3: =AND('Pay Bill'!#REF!,"AAAAAD//ZFc=") -> #REF! | CK3: =AND('Pay Bill'!#REF!,"AAAAAD//ZFg=") -> #REF! | CL3: =AND('Pay Bill'!#REF!,"AAAAAD//ZFk=") -> #REF! | CM3: =AND('Pay Bill'!#REF!,"AAAAAD//ZFo=") -> #REF! | CN3: =AND('Pay Bill'!#REF!,"AAAAAD//ZFs=") -> #REF! | CO3: =AND('Pay Bill'!#REF!,"AAAAAD//ZFw=") -> #REF! | CP3: =AND('Pay Bill'!#REF!,"AAAAAD//ZF0=") -> #REF! | CQ3: =AND('Pay Bill'!#REF!,"AAAAAD//ZF4=") -> #REF! | CR3: =AND('Pay Bill'!#REF!,"AAAAAD//ZF8=") -> #REF! | CS3: =AND('Pay Bill'!#REF!,"AAAAAD//ZGA=") -> #REF! | CT3: =AND('Pay Bill'!#REF!,"AAAAAD//ZGE=") -> #REF! | CU3: =AND('Pay Bill'!#REF!,"AAAAAD//ZGI=") -> #REF! | CV3: =AND('Pay Bill'!#REF!,"AAAAAD//ZGM=") -> #REF! | CW3: =AND('Pay Bill'!#REF!,"AAAAAD//ZGQ=") -> #REF! | CX3: =AND('Pay Bill'!#REF!,"AAAAAD//ZGU=") -> #REF! | CY3: =AND('Pay Bill'!#REF!,"AAAAAD//ZGY=") -> #REF! | CZ3: =AND('Pay Bill'!#REF!,"AAAAAD//ZGc=") -> #REF! | DA3: =IF('Pay Bill'!27:27,"AAAAAD//ZGg=",0) -> 0 | DB3: =AND('Pay Bill'!A27,"AAAAAD//ZGk=") -> #VALUE! | DC3: =AND('Pay Bill'!B27,"AAAAAD//ZGo=") -> #VALUE! | DD3: =AND('Pay Bill'!C27,"AAAAAD//ZGs=") -> #VALUE! | DE3: =AND('Pay Bill'!D27,"AAAAAD//ZGw=") -> #VALUE! | DF3: =AND('Pay Bill'!E27,"AAAAAD//ZG0=") -> #VALUE! | DG3: =AND('Pay Bill'!F27,"AAAAAD//ZG4=") -> #VALUE! | DH3: =AND('Pay Bill'!G27,"AAAAAD//ZG8=") -> #VALUE! | DI3: =AND('Pay Bill'!H27,"AAAAAD//ZHA=") -> #VALUE! | DJ3: =AND('Pay Bill'!I27,"AAAAAD//ZHE=") -> #VALUE! | DK3: =AND('Pay Bill'!J27,"AAAAAD//ZHI=") -> #VALUE! | DL3: =AND('Pay Bill'!#REF!,"AAAAAD//ZHM=") -> #REF! | DM3: =AND('Pay Bill'!#REF!,"AAAAAD//ZHQ=") -> #REF! | DN3: =AND('Pay Bill'!#REF!,"AAAAAD//ZHU=") -> #REF! | DO3: =AND('Pay Bill'!K27,"AAAAAD//ZHY=") -> #VALUE! | DP3: =AND('Pay Bill'!L27,"AAAAAD//ZHc=") -> #VALUE! | DQ3: =AND('Pay Bill'!M27,"AAAAAD//ZHg=") -> #VALUE! | DR3: =AND('Pay Bill'!#REF!,"AAAAAD//ZHk=") -> #REF! | DS3: =AND('Pay Bill'!#REF!,"AAAAAD//ZHo=") -> #REF! | DT3: =AND('Pay Bill'!#REF!,"AAAAAD//ZHs=") -> #REF! | DU3: =AND('Pay Bill'!#REF!,"AAAAAD//ZHw=") -> #REF! | DV3: =AND('Pay Bill'!N27,"AAAAAD//ZH0=") -> #VALUE! | DW3: =IF('Pay Bill'!#REF!,"AAAAAD//ZH4=",0) -> #REF! | DX3: =AND('Pay Bill'!#REF!,"AAAAAD//ZH8=") -> #REF! | DY3: =AND('Pay Bill'!#REF!,"AAAAAD//ZIA=") -> #REF! | DZ3: =AND('Pay Bill'!#REF!,"AAAAAD//ZIE=") -> #REF! | EA3: =AND('Pay Bill'!#REF!,"AAAAAD//ZII=") -> #REF! | EB3: =AND('Pay Bill'!#REF!,"AAAAAD//ZIM=") -> #REF! | EC3: =AND('Pay Bill'!#REF!,"AAAAAD//ZIQ=") -> #REF! | ED3: =AND('Pay Bill'!#REF!,"AAAAAD//ZIU=") -> #REF! | EE3: =AND('Pay Bill'!#REF!,"AAAAAD//ZIY=") -> #REF! | EF3: =AND('Pay Bill'!#REF!,"AAAAAD//ZIc=") -> #REF! | EG3: =AND('Pay Bill'!#REF!,"AAAAAD//ZIg=") -> #REF! | EH3: =AND('Pay Bill'!#REF!,"AAAAAD//ZIk=") -> #REF! | EI3: =AND('Pay Bill'!#REF!,"AAAAAD//ZIo=") -> #REF! | EJ3: =AND('Pay Bill'!#REF!,"AAAAAD//ZIs=") -> #REF! | EK3: =AND('Pay Bill'!#REF!,"AAAAAD//ZIw=") -> #REF! | EL3: =AND('Pay Bill'!#REF!,"AAAAAD//ZI0=") -> #REF! | EM3: =AND('Pay Bill'!#REF!,"AAAAAD//ZI4=") -> #REF! | EN3: =AND('Pay Bill'!#REF!,"AAAAAD//ZI8=") -> #REF! | EO3: =AND('Pay Bill'!#REF!,"AAAAAD//ZJA=") -> #REF! | EP3: =AND('Pay Bill'!#REF!,"AAAAAD//ZJE=") -> #REF! | EQ3: =AND('Pay Bill'!#REF!,"AAAAAD//ZJI=") -> #REF! | ER3: =AND('Pay Bill'!#REF!,"AAAAAD//ZJM=") -> #REF! | ES3: =IF('Pay Bill'!29:29,"AAAAAD//ZJQ=",0) -> 0 | ET3: =AND('Pay Bill'!A29,"AAAAAD//ZJU=") -> #VALUE! | EU3: =AND('Pay Bill'!B29,"AAAAAD//ZJY=") -> #VALUE! | EV3: =AND('Pay Bill'!C29,"AAAAAD//ZJc=") -> #VALUE! | EW3: =AND('Pay Bill'!D29,"AAAAAD//ZJg=") -> #VALUE! | EX3: =AND('Pay Bill'!E29,"AAAAAD//ZJk=") -> #VALUE! | EY3: =AND('Pay Bill'!F29,"AAAAAD//ZJo=") -> #VALUE! | EZ3: =AND('Pay Bill'!G29,"AAAAAD//ZJs=") -> #VALUE! | FA3: =AND('Pay Bill'!H29,"AAAAAD//ZJw=") -> #VALUE! | FB3: =AND('Pay Bill'!I29,"AAAAAD//ZJ0=") -> #VALUE! | FC3: =AND('Pay Bill'!J29,"AAAAAD//ZJ4=") -> #VALUE! | FD3: =AND('Pay Bill'!#REF!,"AAAAAD//ZJ8=") -> #REF! | FE3: =AND('Pay Bill'!#REF!,"AAAAAD//ZKA=") -> #REF! | FF3: =AND('Pay Bill'!#REF!,"AAAAAD//ZKE=") -> #REF! | FG3: =AND('Pay Bill'!K29,"AAAAAD//ZKI=") -> #VALUE! | FH3: =AND('Pay Bill'!L29,"AAAAAD//ZKM=") -> #VALUE! | FI3: =AND('Pay Bill'!M29,"AAAAAD//ZKQ=") -> #VALUE! | FJ3: =AND('Pay Bill'!#REF!,"AAAAAD//ZKU=") -> #REF! | FK3: =AND('Pay Bill'!#REF!,"AAAAAD//ZKY=") -> #REF! | FL3: =AND('Pay Bill'!#REF!,"AAAAAD//ZKc=") -> #REF! | FM3: =AND('Pay Bill'!#REF!,"AAAAAD//ZKg=") -> #REF! | FN3: =AND('Pay Bill'!N29,"AAAAAD//ZKk=") -> #VALUE! | FO3: =IF('Pay Bill'!30:30,"AAAAAD//ZKo=",0) -> 0 | FP3: =AND('Pay Bill'!A30,"AAAAAD//ZKs=") -> #VALUE! | FQ3: =AND('Pay Bill'!B30,"AAAAAD//ZKw=") -> #VALUE! | FR3: =AND('Pay Bill'!C30,"AAAAAD//ZK0=") -> #VALUE! | FS3: =AND('Pay Bill'!D30,"AAAAAD//ZK4=") -> #VALUE! | FT3: =AND('Pay Bill'!E30,"AAAAAD//ZK8=") -> #VALUE! | FU3: =AND('Pay Bill'!F30,"AAAAAD//ZLA=") -> #VALUE! | FV3: =AND('Pay Bill'!G30,"AAAAAD//ZLE=") -> #VALUE! | FW3: =AND('Pay Bill'!H30,"AAAAAD//ZLI=") -> #VALUE! | FX3: =AND('Pay Bill'!I30,"AAAAAD//ZLM=") -> #VALUE! | FY3: =AND('Pay Bill'!J30,"AAAAAD//ZLQ=") -> #VALUE! | FZ3: =AND('Pay Bill'!#REF!,"AAAAAD//ZLU=") -> #REF! | GA3: =AND('Pay Bill'!#REF!,"AAAAAD//ZLY=") -> #REF! | GB3: =AND('Pay Bill'!#REF!,"AAAAAD//ZLc=") -> #REF! | GC3: =AND('Pay Bill'!K30,"AAAAAD//ZLg=") -> #VALUE! | GD3: =AND('Pay Bill'!L30,"AAAAAD//ZLk=") -> #VALUE! | GE3: =AND('Pay Bill'!M30,"AAAAAD//ZLo=") -> #VALUE! | GF3: =AND('Pay Bill'!#REF!,"AAAAAD//ZLs=") -> #REF! | GG3: =AND('Pay Bill'!#REF!,"AAAAAD//ZLw=") -> #REF! | GH3: =AND('Pay Bill'!#REF!,"AAAAAD//ZL0=") -> #REF! | GI3: =AND('Pay Bill'!#REF!,"AAAAAD//ZL4=") -> #REF! | GJ3: =AND('Pay Bill'!N30,"AAAAAD//ZL8=") -> #VALUE! | GK3: =IF('Pay Bill'!31:31,"AAAAAD//ZMA=",0) -> 0 | GL3: =AND('Pay Bill'!A31,"AAAAAD//ZME=") -> #VALUE! | GM3: =AND('Pay Bill'!B31,"AAAAAD//ZMI=") -> #VALUE! | GN3: =AND('Pay Bill'!C31,"AAAAAD//ZMM=") -> #VALUE! | GO3: =AND('Pay Bill'!D31,"AAAAAD//ZMQ=") -> #VALUE! | GP3: =AND('Pay Bill'!E31,"AAAAAD//ZMU=") -> #VALUE! | GQ3: =AND('Pay Bill'!F31,"AAAAAD//ZMY=") -> #VALUE! | GR3: =AND('Pay Bill'!G31,"AAAAAD//ZMc=") -> #VALUE! | GS3: =AND('Pay Bill'!H31,"AAAAAD//ZMg=") -> #VALUE! | GT3: =AND('Pay Bill'!I31,"AAAAAD//ZMk=") -> #VALUE! | GU3: =AND('Pay Bill'!J31,"AAAAAD//ZMo=") -> #VALUE! | GV3: =AND('Pay Bill'!#REF!,"AAAAAD//ZMs=") -> #REF! | GW3: =AND('Pay Bill'!#REF!,"AAAAAD//ZMw=") -> #REF! | GX3: =AND('Pay Bill'!#REF!,"AAAAAD//ZM0=") -> #REF! | GY3: =AND('Pay Bill'!K31,"AAAAAD//ZM4=") -> #VALUE! | GZ3: =AND('Pay Bill'!L31,"AAAAAD//ZM8=") -> #VALUE! | HA3: =AND('Pay Bill'!M31,"AAAAAD//ZNA=") -> #VALUE! | HB3: =AND('Pay Bill'!#REF!,"AAAAAD//ZNE=") -> #REF! | HC3: =AND('Pay Bill'!#REF!,"AAAAAD//ZNI=") -> #REF! | HD3: =AND('Pay Bill'!#REF!,"AAAAAD//ZNM=") -> #REF! | HE3: =AND('Pay Bill'!#REF!,"AAAAAD//ZNQ=") -> #REF! | HF3: =AND('Pay Bill'!N31,"AAAAAD//ZNU=") -> #VALUE! | HG3: =IF('Pay Bill'!32:32,"AAAAAD//ZNY=",0) -> 0 | HH3: =AND('Pay Bill'!A32,"AAAAAD//ZNc=") -> #VALUE! | HI3: =AND('Pay Bill'!B32,"AAAAAD//ZNg=") -> #VALUE! | HJ3: =AND('Pay Bill'!C32,"AAAAAD//ZNk=") -> #VALUE! | HK3: =AND('Pay Bill'!D32,"AAAAAD//ZNo=") -> #VALUE! | HL3: =AND('Pay Bill'!E32,"AAAAAD//ZNs=") -> #VALUE! | HM3: =AND('Pay Bill'!F32,"AAAAAD//ZNw=") -> #VALUE! | HN3: =AND('Pay Bill'!G32,"AAAAAD//ZN0=") -> #VALUE! | HO3: =AND('Pay Bill'!H32,"AAAAAD//ZN4=") -> #VALUE! | HP3: =AND('Pay Bill'!I32,"AAAAAD//ZN8=") -> #VALUE! | HQ3: =AND('Pay Bill'!J32,"AAAAAD//ZOA=") -> #VALUE! | HR3: =AND('Pay Bill'!#REF!,"AAAAAD//ZOE=") -> #REF! | HS3: =AND('Pay Bill'!#REF!,"AAAAAD//ZOI=") -> #REF! | HT3: =AND('Pay Bill'!#REF!,"AAAAAD//ZOM=") -> #REF! | HU3: =AND('Pay Bill'!K32,"AAAAAD//ZOQ=") -> #VALUE! | HV3: =AND('Pay Bill'!L32,"AAAAAD//ZOU=") -> #VALUE! | HW3: =AND('Pay Bill'!M32,"AAAAAD//ZOY=") -> #VALUE! | HX3: =AND('Pay Bill'!#REF!,"AAAAAD//ZOc=") -> #REF! | HY3: =AND('Pay Bill'!#REF!,"AAAAAD//ZOg=") -> #REF! | HZ3: =AND('Pay Bill'!#REF!,"AAAAAD//ZOk=") -> #REF! | IA3: =AND('Pay Bill'!#REF!,"AAAAAD//ZOo=") -> #REF! | IB3: =AND('Pay Bill'!N32,"AAAAAD//ZOs=") -> #VALUE! | IC3: =IF('Pay Bill'!38:38,"AAAAAD//ZOw=",0) -> 0 | ID3: =AND('Pay Bill'!A38,"AAAAAD//ZO0=") -> #VALUE! | IE3: =AND('Pay Bill'!B38,"AAAAAD//ZO4=") -> #VALUE! | IF3: =AND('Pay Bill'!C38,"AAAAAD//ZO8=") -> #VALUE! | IG3: =AND('Pay Bill'!D38,"AAAAAD//ZPA=") -> #VALUE! | IH3: =AND('Pay Bill'!E38,"AAAAAD//ZPE=") -> #VALUE! | II3: =AND('Pay Bill'!F38,"AAAAAD//ZPI=") -> #VALUE! | IJ3: =AND('Pay Bill'!G38,"AAAAAD//ZPM=") -> #VALUE! | IK3: =AND('Pay Bill'!H38,"AAAAAD//ZPQ=") -> #VALUE! | IL3: =AND('Pay Bill'!I38,"AAAAAD//ZPU=") -> #VALUE! | IM3: =AND('Pay Bill'!J38,"AAAAAD//ZPY=") -> #VALUE! | IN3: =AND('Pay Bill'!#REF!,"AAAAAD//ZPc=") -> #REF! | IO3: =AND('Pay Bill'!#REF!,"AAAAAD//ZPg=") -> #REF! | IP3: =AND('Pay Bill'!#REF!,"AAAAAD//ZPk=") -> #REF! | IQ3: =AND('Pay Bill'!K38,"AAAAAD//ZPo=") -> #VALUE! | IR3: =AND('Pay Bill'!L38,"AAAAAD//ZPs=") -> #VALUE! | IS3: =AND('Pay Bill'!M38,"AAAAAD//ZPw=") -> #VALUE! | IT3: =AND('Pay Bill'!#REF!,"AAAAAD//ZP0=") -> #REF! | IU3: =AND('Pay Bill'!#REF!,"AAAAAD//ZP4=") -> #REF! | IV3: =AND('Pay Bill'!#REF!,"AAAAAD//ZP8=") -> #REF!
A4: =AND('Pay Bill'!#REF!,"AAAAAFBt1QA=") -> #REF! | B4: =AND('Pay Bill'!N38,"AAAAAFBt1QE=") -> #VALUE! | C4: =IF('Pay Bill'!39:39,"AAAAAFBt1QI=",0) -> 0 | D4: =AND('Pay Bill'!A39,"AAAAAFBt1QM=") -> #VALUE! | E4: =AND('Pay Bill'!B39,"AAAAAFBt1QQ=") -> #VALUE! | F4: =AND('Pay Bill'!C39,"AAAAAFBt1QU=") -> #VALUE! | G4: =AND('Pay Bill'!D39,"AAAAAFBt1QY=") -> #VALUE! | H4: =AND('Pay Bill'!E39,"AAAAAFBt1Qc=") -> #VALUE! | I4: =AND('Pay Bill'!F39,"AAAAAFBt1Qg=") -> #VALUE! | J4: =AND('Pay Bill'!G39,"AAAAAFBt1Qk=") -> #VALUE! | K4: =AND('Pay Bill'!H39,"AAAAAFBt1Qo=") -> #VALUE! | L4: =AND('Pay Bill'!I39,"AAAAAFBt1Qs=") -> #VALUE! | M4: =AND('Pay Bill'!J39,"AAAAAFBt1Qw=") -> #VALUE! | N4: =AND('Pay Bill'!#REF!,"AAAAAFBt1Q0=") -> #REF! | O4: =AND('Pay Bill'!#REF!,"AAAAAFBt1Q4=") -> #REF! | P4: =AND('Pay Bill'!#REF!,"AAAAAFBt1Q8=") -> #REF! | Q4: =AND('Pay Bill'!K39,"AAAAAFBt1RA=") -> #VALUE! | R4: =AND('Pay Bill'!L39,"AAAAAFBt1RE=") -> #VALUE! | S4: =AND('Pay Bill'!M39,"AAAAAFBt1RI=") -> #VALUE! | T4: =AND('Pay Bill'!#REF!,"AAAAAFBt1RM=") -> #REF! | U4: =AND('Pay Bill'!#REF!,"AAAAAFBt1RQ=") -> #REF! | V4: =AND('Pay Bill'!#REF!,"AAAAAFBt1RU=") -> #REF! | W4: =AND('Pay Bill'!#REF!,"AAAAAFBt1RY=") -> #REF! | X4: =AND('Pay Bill'!N39,"AAAAAFBt1Rc=") -> #VALUE! | Y4: =IF('Pay Bill'!40:40,"AAAAAFBt1Rg=",0) -> 0 | Z4: =AND('Pay Bill'!A40,"AAAAAFBt1Rk=") -> #VALUE! | AA4: =AND('Pay Bill'!B40,"AAAAAFBt1Ro=") -> #VALUE! | AB4: =AND('Pay Bill'!C40,"AAAAAFBt1Rs=") -> #VALUE! | AC4: =AND('Pay Bill'!D40,"AAAAAFBt1Rw=") -> #VALUE! | AD4: =AND('Pay Bill'!E40,"AAAAAFBt1R0=") -> #VALUE! | AE4: =AND('Pay Bill'!F40,"AAAAAFBt1R4=") -> #VALUE! | AF4: =AND('Pay Bill'!G40,"AAAAAFBt1R8=") -> #VALUE! | AG4: =AND('Pay Bill'!H40,"AAAAAFBt1SA=") -> #VALUE! | AH4: =AND('Pay Bill'!I40,"AAAAAFBt1SE=") -> #VALUE! | AI4: =AND('Pay Bill'!J40,"AAAAAFBt1SI=") -> #VALUE! | AJ4: =AND('Pay Bill'!#REF!,"AAAAAFBt1SM=") -> #REF! | AK4: =AND('Pay Bill'!#REF!,"AAAAAFBt1SQ=") -> #REF! | AL4: =AND('Pay Bill'!#REF!,"AAAAAFBt1SU=") -> #REF! | AM4: =AND('Pay Bill'!K40,"AAAAAFBt1SY=") -> #VALUE! | AN4: =AND('Pay Bill'!L40,"AAAAAFBt1Sc=") -> #VALUE! | AO4: =AND('Pay Bill'!M40,"AAAAAFBt1Sg=") -> #VALUE! | AP4: =AND('Pay Bill'!#REF!,"AAAAAFBt1Sk=") -> #REF! | AQ4: =AND('Pay Bill'!#REF!,"AAAAAFBt1So=") -> #REF! | AR4: =AND('Pay Bill'!#REF!,"AAAAAFBt1Ss=") -> #REF! | AS4: =AND('Pay Bill'!#REF!,"AAAAAFBt1Sw=") -> #REF! | AT4: =AND('Pay Bill'!N40,"AAAAAFBt1S0=") -> #VALUE! | AU4: =IF('Pay Bill'!41:41,"AAAAAFBt1S4=",0) -> 0 | AV4: =AND('Pay Bill'!A41,"AAAAAFBt1S8=") -> #VALUE! | AW4: =AND('Pay Bill'!B41,"AAAAAFBt1TA=") -> #VALUE! | AX4: =AND('Pay Bill'!C41,"AAAAAFBt1TE=") -> #VALUE! | AY4: =AND('Pay Bill'!D41,"AAAAAFBt1TI=") -> #VALUE! | AZ4: =AND('Pay Bill'!E41,"AAAAAFBt1TM=") -> #VALUE! | BA4: =AND('Pay Bill'!F41,"AAAAAFBt1TQ=") -> #VALUE! | BB4: =AND('Pay Bill'!G41,"AAAAAFBt1TU=") -> #VALUE! | BC4: =AND('Pay Bill'!H41,"AAAAAFBt1TY=") -> #VALUE! | BD4: =AND('Pay Bill'!I41,"AAAAAFBt1Tc=") -> #VALUE! | BE4: =AND('Pay Bill'!J41,"AAAAAFBt1Tg=") -> #VALUE! | BF4: =AND('Pay Bill'!#REF!,"AAAAAFBt1Tk=") -> #REF! | BG4: =AND('Pay Bill'!#REF!,"AAAAAFBt1To=") -> #REF! | BH4: =AND('Pay Bill'!#REF!,"AAAAAFBt1Ts=") -> #REF! | BI4: =AND('Pay Bill'!K41,"AAAAAFBt1Tw=") -> #VALUE! | BJ4: =AND('Pay Bill'!L41,"AAAAAFBt1T0=") -> #VALUE! | BK4: =AND('Pay Bill'!M41,"AAAAAFBt1T4=") -> #VALUE! | BL4: =AND('Pay Bill'!#REF!,"AAAAAFBt1T8=") -> #REF! | BM4: =AND('Pay Bill'!#REF!,"AAAAAFBt1UA=") -> #REF! | BN4: =AND('Pay Bill'!#REF!,"AAAAAFBt1UE=") -> #REF! | BO4: =AND('Pay Bill'!#REF!,"AAAAAFBt1UI=") -> #REF! | BP4: =AND('Pay Bill'!N41,"AAAAAFBt1UM=") -> #VALUE! | BQ4: =IF('Pay Bill'!42:42,"AAAAAFBt1UQ=",0) -> 0 | BR4: =IF('Pay Bill'!43:43,"AAAAAFBt1UU=",0) -> 0 | BS4: =IF('Pay Bill'!44:44,"AAAAAFBt1UY=",0) -> 0 | BT4: =IF('Pay Bill'!45:45,"AAAAAFBt1Uc=",0) -> 0 | BU4: =IF('Pay Bill'!46:46,"AAAAAFBt1Ug=",0) -> 0 | BV4: =IF('Pay Bill'!47:47,"AAAAAFBt1Uk=",0) -> 0 | BW4: =IF('Pay Bill'!48:48,"AAAAAFBt1Uo=",0) -> 0 | BX4: =IF('Pay Bill'!49:49,"AAAAAFBt1Us=",0) -> 0 | BY4: =IF('Pay Bill'!50:50,"AAAAAFBt1Uw=",0) -> 0 | BZ4: =IF('Pay Bill'!51:51,"AAAAAFBt1U0=",0) -> 0 | CA4: =IF('Pay Bill'!52:52,"AAAAAFBt1U4=",0) -> 0 | CB4: =IF('Pay Bill'!53:53,"AAAAAFBt1U8=",0) -> 0 | CC4: =IF('Pay Bill'!54:54,"AAAAAFBt1VA=",0) -> 0 | CD4: =IF('Pay Bill'!55:55,"AAAAAFBt1VE=",0) -> 0 | CE4: =IF('Pay Bill'!56:56,"AAAAAFBt1VI=",0) -> 0 | CF4: =IF('Pay Bill'!57:57,"AAAAAFBt1VM=",0) -> 0 | CG4: =IF('Pay Bill'!58:58,"AAAAAFBt1VQ=",0) -> 0 | CH4: =IF('Pay Bill'!59:59,"AAAAAFBt1VU=",0) -> 0 | CI4: =IF('Pay Bill'!60:60,"AAAAAFBt1VY=",0) -> 0 | CJ4: =IF('Pay Bill'!61:61,"AAAAAFBt1Vc=",0) -> 0 | CK4: =IF('Pay Bill'!62:62,"AAAAAFBt1Vg=",0) -> 0 | CL4: =IF('Pay Bill'!63:63,"AAAAAFBt1Vk=",0) -> 0 | CM4: =IF('Pay Bill'!64:64,"AAAAAFBt1Vo=",0) -> 0 | CN4: =IF('Pay Bill'!65:65,"AAAAAFBt1Vs=",0) -> 0 | CO4: =IF('Pay Bill'!66:66,"AAAAAFBt1Vw=",0) -> 0 | CP4: =IF('Pay Bill'!67:67,"AAAAAFBt1V0=",0) -> 0 | CQ4: =IF('Pay Bill'!68:68,"AAAAAFBt1V4=",0) -> 0 | CR4: =IF('Pay Bill'!69:69,"AAAAAFBt1V8=",0) -> 0 | CS4: =IF('Pay Bill'!70:70,"AAAAAFBt1WA=",0) -> 0 | CT4: =IF('Pay Bill'!71:71,"AAAAAFBt1WE=",0) -> 0 | CU4: =IF('Pay Bill'!72:72,"AAAAAFBt1WI=",0) -> 0 | CV4: =IF('Pay Bill'!73:73,"AAAAAFBt1WM=",0) -> 0 | CW4: =IF('Pay Bill'!74:74,"AAAAAFBt1WQ=",0) -> 0 | CX4: =IF('Pay Bill'!75:75,"AAAAAFBt1WU=",0) -> 0 | CY4: =IF('Pay Bill'!76:76,"AAAAAFBt1WY=",0) -> 0 | CZ4: =IF('Pay Bill'!77:77,"AAAAAFBt1Wc=",0) -> 0 | DA4: =IF('Pay Bill'!78:78,"AAAAAFBt1Wg=",0) -> 0 | DB4: =IF('Pay Bill'!79:79,"AAAAAFBt1Wk=",0) -> 0 | DC4: =IF('Pay Bill'!80:80,"AAAAAFBt1Wo=",0) -> 0 | DD4: =IF('Pay Bill'!81:81,"AAAAAFBt1Ws=",0) -> 0 | DE4: =IF('Pay Bill'!82:82,"AAAAAFBt1Ww=",0) -> 0 | DF4: =IF('Pay Bill'!83:83,"AAAAAFBt1W0=",0) -> 0 | DG4: =IF('Pay Bill'!84:84,"AAAAAFBt1W4=",0) -> 0 | DH4: =IF('Pay Bill'!85:85,"AAAAAFBt1W8=",0) -> 0 | DI4: =IF('Pay Bill'!86:86,"AAAAAFBt1XA=",0) -> 0 | DJ4: =IF('Pay Bill'!87:87,"AAAAAFBt1XE=",0) -> 0 | DK4: =IF('Pay Bill'!88:88,"AAAAAFBt1XI=",0) -> 0 | DL4: =IF('Pay Bill'!89:89,"AAAAAFBt1XM=",0) -> 0 | DM4: =IF('Pay Bill'!90:90,"AAAAAFBt1XQ=",0) -> 0 | DN4: =IF('Pay Bill'!91:91,"AAAAAFBt1XU=",0) -> 0 | DO4: =IF('Pay Bill'!92:92,"AAAAAFBt1XY=",0) -> 0 | DP4: =IF('Pay Bill'!93:93,"AAAAAFBt1Xc=",0) -> 0 | DQ4: =IF('Pay Bill'!94:94,"AAAAAFBt1Xg=",0) -> 0 | DR4: =IF('Pay Bill'!95:95,"AAAAAFBt1Xk=",0) -> 0 | DS4: =IF('Pay Bill'!96:96,"AAAAAFBt1Xo=",0) -> 0 | DT4: =IF('Pay Bill'!97:97,"AAAAAFBt1Xs=",0) -> 0 | DU4: =IF('Pay Bill'!98:98,"AAAAAFBt1Xw=",0) -> 0 | DV4: =IF('Pay Bill'!99:99,"AAAAAFBt1X0=",0) -> 0 | DW4: =IF('Pay Bill'!100:100,"AAAAAFBt1X4=",0) -> 0 | DX4: =IF('Pay Bill'!101:101,"AAAAAFBt1X8=",0) -> 0 | DY4: =IF('Pay Bill'!102:102,"AAAAAFBt1YA=",0) -> 0 | DZ4: =IF('Pay Bill'!103:103,"AAAAAFBt1YE=",0) -> 0 | EA4: =IF('Pay Bill'!104:104,"AAAAAFBt1YI=",0) -> 0 | EB4: =IF('Pay Bill'!105:105,"AAAAAFBt1YM=",0) -> 0 | EC4: =IF('Pay Bill'!106:106,"AAAAAFBt1YQ=",0) -> 0 | ED4: =IF('Pay Bill'!A:A,"AAAAAFBt1YU=",0) -> #VALUE! | EE4: =IF('Pay Bill'!B:B,"AAAAAFBt1YY=",0) -> 0 | EF4: =IF('Pay Bill'!C:C,"AAAAAFBt1Yc=",0) -> 0 | EG4: =IF('Pay Bill'!D:D,"AAAAAFBt1Yg=",0) -> 0 | EH4: =IF('Pay Bill'!E:E,"AAAAAFBt1Yk=",0) -> 0 | EI4: =IF('Pay Bill'!F:F,"AAAAAFBt1Yo=",0) -> 0 | EJ4: =IF('Pay Bill'!G:G,"AAAAAFBt1Ys=",0) -> 0 | EK4: =IF('Pay Bill'!H:H,"AAAAAFBt1Yw=",0) -> 0 | EL4: =IF('Pay Bill'!I:I,"AAAAAFBt1Y0=",0) -> 0 | EM4: =IF('Pay Bill'!J:J,"AAAAAFBt1Y4=",0) -> 0 | EN4: =IF('Pay Bill'!#REF!,"AAAAAFBt1Y8=",0) -> #REF! | EO4: =IF('Pay Bill'!#REF!,"AAAAAFBt1ZA=",0) -> #REF! | EP4: =IF('Pay Bill'!#REF!,"AAAAAFBt1ZE=",0) -> #REF! | EQ4: =IF('Pay Bill'!K:K,"AAAAAFBt1ZI=",0) -> 0 | ER4: =IF('Pay Bill'!L:L,"AAAAAFBt1ZM=",0) -> 0 | ES4: =IF('Pay Bill'!M:M,"AAAAAFBt1ZQ=",0) -> 0 | ET4: =IF('Pay Bill'!#REF!,"AAAAAFBt1ZU=",0) -> #REF! | EU4: =IF('Pay Bill'!#REF!,"AAAAAFBt1ZY=",0) -> #REF! | EV4: =IF('Pay Bill'!#REF!,"AAAAAFBt1Zc=",0) -> #REF! | EW4: =IF('Pay Bill'!#REF!,"AAAAAFBt1Zg=",0) -> #REF! | EX4: =IF('Pay Bill'!N:N,"AAAAAFBt1Zk=",0) -> 0 | EY4: AAAAAFBt1Zo=
